Workbook

Sheet nexus_theme_level
A1: lbh9517_175126 | B1: lbh9517_175126 | C1: lbh9517_175126 | D1: lbh9517_175126 | E1: lbh9517_175126 | F1: lbh9517_175126 | G1: lbh9517_175126 | H1: lbh9517_175126 | I1: lbh9517_175126 | J1: lbh9517_175126 | K1: lbh9517_175126 | L1: lbh9517_175126 | M1: lbh9517_175126
A2: 고유값 | C2: 테마 id | D2: 패스 레벨 | E2: 필요 exp 양 | F2: 완료 보상 1 | G2: 보상 값 1 | H2: 해금될 도감 스토리 id | I2: y시 메인 리워드 | J2: 등급 설정 | K2: 세트 설정 | L2: 장비 옵션 설정 | M2: 장비 강화 LV 설정(현재 15만 사용 가능)
A3: id | B3: export_id | C3: theme_id | D3: level | E3: need_exp_value | F3: reward_id_1 | G3: reward_value_1 | H3: dic_collect_story | I3: main_reward | J3: *grade_rate_1 | K3: *set_drop_1 | L3: *equip_op_1 | M3: *equip_enchant_lv_1
A4: =C4&"_pass_"&D4 -> s1_pass_1 | B4: lbh9517_175126 | C4: s1 | D4: 1 | E4: 50 | F4: to_gold | G4: 50000 | H4: nexus_s1_story_001
A5: =C5&"_pass_"&D5 -> s1_pass_2 | B5: lbh9517_175126 | C5: s1 | D5: 2 | E5: =E4+ROUNDUP($E$4*D4,-1) -> 100 | F5: to_stigma | G5: 150
A6: =C6&"_pass_"&D6 -> s1_pass_3 | B6: lbh9517_175126 | C6: s1 | D6: 3 | E6: =E5+ROUNDUP($E$4*D5,-1) -> 200 | F6: to_ticketrare | G6: 5 | H6: nexus_s1_story_002
A7: =C7&"_pass_"&D7 -> s1_pass_4 | B7: lbh9517_175126 | C7: s1 | D7: 4 | E7: =E6+ROUNDUP($E$4*D6,-1) -> 350 | F7: to_gold | G7: 75000
A8: =C8&"_pass_"&D8 -> s1_pass_5 | B8: lbh9517_175126 | C8: s1 | D8: 5 | E8: =E7+ROUNDUP($E$4*D7,-1) -> 550 | F8: to_crystal | G8: 30 | H8: nexus_s1_story_003
A9: =C9&"_pass_"&D9 -> s1_pass_6 | B9: lbh9517_175126 | C9: s1 | D9: 6 | E9: =E8+ROUNDUP($E$4*D8,-1) -> 800 | F9: to_powder | G9: 15
A10: =C10&"_pass_"&D10 -> s1_pass_7 | B10: lbh9517_175126 | C10: s1 | D10: 7 | E10: =E9+ROUNDUP($E$4*D9,-1) -> 1100 | F10: to_ticketrare_wish | G10: 3 | H10: nexus_s1_story_004
A11: =C11&"_pass_"&D11 -> s1_pass_8 | B11: lbh9517_175126 | C11: s1 | D11: 8 | E11: =E10+ROUNDUP($E$4*D10,-1) -> 1450 | F11: to_gold | G11: 100000
A12: =C12&"_pass_"&D12 -> s1_pass_9 | B12: lbh9517_175126 | C12: s1 | D12: 9 | E12: =E11+ROUNDUP($E$4*D11,-1) -> 1850 | F12: to_stigma | G12: 300 | H12: nexus_s1_story_005
A13: =C13&"_pass_"&D13 -> s1_pass_10 | B13: lbh9517_175126 | C13: s1 | D13: 10 | E13: =E12+ROUNDUP($E$4*D12,-1) -> 2300 | F13: to_crystal | G13: 100 | I13: y
A14: =C14&"_pass_"&D14 -> s1_pass_11 | B14: lbh9517_175126 | C14: s1 | D14: 11 | E14: =E13+ROUNDUP($E$4*D13,-1) -> 2800 | F14: to_gold | G14: 50000 | H14: nexus_s1_story_006
A15: =C15&"_pass_"&D15 -> s1_pass_12 | B15: lbh9517_175126 | C15: s1 | D15: 12 | E15: =E14+ROUNDUP($E$4*D14,-1) -> 3350 | F15: to_stigma | G15: 150
A16: =C16&"_pass_"&D16 -> s1_pass_13 | B16: lbh9517_175126 | C16: s1 | D16: 13 | E16: =E15+ROUNDUP($E$4*D15,-1) -> 3950 | F16: to_ticketrare | G16: 5 | H16: nexus_s1_story_007
A17: =C17&"_pass_"&D17 -> s1_pass_14 | B17: lbh9517_175126 | C17: s1 | D17: 14 | E17: =E16+ROUNDUP($E$4*D16,-1) -> 4600 | F17: to_gold | G17: 75000
A18: =C18&"_pass_"&D18 -> s1_pass_15 | B18: lbh9517_175126 | C18: s1 | D18: 15 | E18: =E17+ROUNDUP($E$4*D17,-1) -> 5300 | F18: to_crystal | G18: 30 | H18: nexus_s1_story_008
A19: =C19&"_pass_"&D19 -> s1_pass_16 | B19: lbh9517_175126 | C19: s1 | D19: 16 | E19: =E18+ROUNDUP($E$4*D18,-1) -> 6050 | F19: to_powder | G19: 15
A20: =C20&"_pass_"&D20 -> s1_pass_17 | B20: lbh9517_175126 | C20: s1 | D20: 17 | E20: =E19+ROUNDUP($E$4*D19,-1) -> 6850 | F20: to_ticketrare_wish | G20: 3 | H20: nexus_s1_story_009
A21: =C21&"_pass_"&D21 -> s1_pass_18 | B21: lbh9517_175126 | C21: s1 | D21: 18 | E21: =E20+ROUNDUP($E$4*D20,-1) -> 7700 | F21: to_gold | G21: 100000
A22: =C22&"_pass_"&D22 -> s1_pass_19 | B22: lbh9517_175126 | C22: s1 | D22: 19 | E22: =E21+ROUNDUP($E$4*D21,-1) -> 8600 | F22: to_stigma | G22: 300 | H22: nexus_s1_story_010
A23: =C23&"_pass_"&D23 -> s1_pass_20 | B23: lbh9517_175126 | C23: s1 | D23: 20 | E23: =E22+ROUNDUP($E$4*D22,-1) -> 9550 | F23: to_ticketrare | G23: 20 | I23: y
A24: =C24&"_pass_"&D24 -> s1_pass_21 | B24: lbh9517_175126 | C24: s1 | D24: 21 | E24: =E23+ROUNDUP($E$4*D23,-1) -> 10550 | F24: to_gold | G24: 50000 | H24: nexus_s1_story_011
A25: =C25&"_pass_"&D25 -> s1_pass_22 | B25: lbh9517_175126 | C25: s1 | D25: 22 | E25: =E24+ROUNDUP($E$4*D24,-1) -> 11600 | F25: to_stigma | G25: 150
A26: =C26&"_pass_"&D26 -> s1_pass_23 | B26: lbh9517_175126 | C26: s1 | D26: 23 | E26: =E25+ROUNDUP($E$4*D25,-1) -> 12700 | F26: to_ticketrare | G26: 5 | H26: nexus_s1_story_012
A27: =C27&"_pass_"&D27 -> s1_pass_24 | B27: lbh9517_175126 | C27: s1 | D27: 24 | E27: =E26+ROUNDUP($E$4*D26,-1) -> 13850 | F27: to_gold | G27: 75000
A28: =C28&"_pass_"&D28 -> s1_pass_25 | B28: lbh9517_175126 | C28: s1 | D28: 25 | E28: =E27+ROUNDUP($E$4*D27,-1) -> 15050 | F28: to_crystal | G28: 30 | H28: nexus_s1_story_013
A29: =C29&"_pass_"&D29 -> s1_pass_26 | B29: lbh9517_175126 | C29: s1 | D29: 26 | E29: =E28+ROUNDUP($E$4*D28,-1) -> 16300 | F29: to_powder | G29: 15
A30: =C30&"_pass_"&D30 -> s1_pass_27 | B30: lbh9517_175126 | C30: s1 | D30: 27 | E30: =E29+ROUNDUP($E$4*D29,-1) -> 17600 | F30: to_ticketrare_wish | G30: 3 | H30: nexus_s1_story_014
A31: =C31&"_pass_"&D31 -> s1_pass_28 | B31: lbh9517_175126 | C31: s1 | D31: 28 | E31: =E30+ROUNDUP($E$4*D30,-1) -> 18950 | F31: to_gold | G31: 100000
A32: =C32&"_pass_"&D32 -> s1_pass_29 | B32: lbh9517_175126 | C32: s1 | D32: 29 | E32: =E31+ROUNDUP($E$4*D31,-1) -> 20350 | F32: to_stigma | G32: 300 | H32: nexus_s1_story_015
A33: =C33&"_pass_"&D33 -> s1_pass_30 | B33: lbh9517_175126 | C33: s1 | D33: 30 | E33: =E32+ROUNDUP($E$4*D32,-1) -> 21800 | F33: to_powder | G33: 60 | I33: y
A34: =C34&"_pass_"&D34 -> s1_pass_31 | B34: lbh9517_175126 | C34: s1 | D34: 31 | E34: =E33+ROUNDUP($E$4*D33,-1) -> 23300 | F34: to_gold | G34: 50000
A35: =C35&"_pass_"&D35 -> s1_pass_32 | B35: lbh9517_175126 | C35: s1 | D35: 32 | E35: =E34+ROUNDUP($E$4*D34,-1) -> 24850 | F35: to_stigma | G35: 150
A36: =C36&"_pass_"&D36 -> s1_pass_33 | B36: lbh9517_175126 | C36: s1 | D36: 33 | E36: =E35+ROUNDUP($E$4*D35,-1) -> 26450 | F36: to_ticketrare | G36: 5
A37: =C37&"_pass_"&D37 -> s1_pass_34 | B37: lbh9517_175126 | C37: s1 | D37: 34 | E37: =E36+ROUNDUP($E$4*D36,-1) -> 28100 | F37: to_gold | G37: 75000
A38: =C38&"_pass_"&D38 -> s1_pass_35 | B38: lbh9517_175126 | C38: s1 | D38: 35 | E38: =E37+ROUNDUP($E$4*D37,-1) -> 29800 | F38: to_crystal | G38: 30
A39: =C39&"_pass_"&D39 -> s1_pass_36 | B39: lbh9517_175126 | C39: s1 | D39: 36 | E39: =E38+ROUNDUP($E$4*D38,-1) -> 31550 | F39: to_powder | G39: 15
A40: =C40&"_pass_"&D40 -> s1_pass_37 | B40: lbh9517_175126 | C40: s1 | D40: 37 | E40: =E39+ROUNDUP($E$4*D39,-1) -> 33350 | F40: to_ticketrare_wish | G40: 3
...

Sheet nexus_hall_level
A1: lbh9517_175126 | B1: lbh9517_175126 | C1: lbh9517_175126 | D1: lbh9517_175126 | E1: lbh9517_175126 | F1: lbh9517_175126 | G1: lbh9517_175126 | H1: lbh9517_175126 | I1: lbh9517_175126 | J1: lbh9517_175126 | K1: lbh9517_175126 | L1: lbh9517_175126 | M1: lbh9517_175126 | N1: lbh9517_175126 | O1: lbh9517_175126 | P1: lbh9517_175126 | Q1: lbh9517_175126 | R1: lbh9517_175126 | S1: lbh9517_175126 | T1: lbh9517_175126 | U1: lbh9517_175126 | V1: lbh9517_175126 | W1: lbh9517_175126
A2: 고유값 | C2: 테마 id | D2: 레벨 | E2: 레벨 별 배경 | F2: 레벨 별 이미지 | G2: 레벨 상승 필요 아이템 | H2: 레벨 상승 필요 개수 | I2: 노드 구획 해방 권한 | J2: 리워드 타입 | K2: 리워드 id | L2: 리워드 개수 | M2: 등급 설정 | N2: 세트 설정 | O2: 장비 옵션 설정 | P2: 장비 강화 LV 설정(현재 15만 사용 가능) | Q2: 리워드 타입 | R2: 리워드 id | S2: 리워드 개수 | T2: 등급 설정 | U2: 세트 설정 | V2: 장비 옵션 설정 | W2: 장비 강화 LV 설정(현재 15만 사용 가능)
A3: id | B3: export_id | C3: theme_id | D3: level | E3: level_bg | F3: level_image | G3: level_require_item_id | H3: level_require_item_value | I3: node_permission | J3: reward_type_1 | K3: reward_id_1 | L3: reward_1_value | M3: *grade_rate_1 | N3: *set_drop_1 | O3: *equip_op_1 | P3: *equip_enchant_lv_1 | Q3: reward_type_2 | R3: reward_id_2 | S3: reward_2_value | T3: *grade_rate_2 | U3: *set_drop_2 | V3: *equip_op_2 | W3: *equip_enchant_lv_2
A4: =C4&"_level_"&D4 -> s1_level_1 | B4: lbh9517_175126 | C4: s1 | D4: 1 | E4: bg_nexus1_00pct | F4: nexus_hall_lv_01 | G4: to_gold | H4: 0 | I4: 1 | J4: node | K4: to_gold | L4: 100000 | Q4: item | R4: to_gold | S4: 50000
A5: =C5&"_level_"&D5 -> s1_level_2 | B5: lbh9517_175126 | C5: s1 | D5: 2 | E5: bg_nexus1_00pct | F5: nexus_hall_lv_02 | G5: to_gold | H5: 200 | I5: 1 | J5: item | K5: to_gold | L5: 100000 | Q5: item | R5: to_stigma | S5: 200
A6: =C6&"_level_"&D6 -> s1_level_3 | B6: lbh9517_175126 | C6: s1 | D6: 3 | E6: bg_nexus1_25pct | F6: nexus_hall_lv_03 | G6: to_gold | H6: 450 | I6: 2 | J6: node | K6: to_gold | L6: 100000 | Q6: item | R6: to_crystal | S6: 50
A7: =C7&"_level_"&D7 -> s1_level_4 | B7: lbh9517_175126 | C7: s1 | D7: 4 | E7: bg_nexus1_25pct | F7: nexus_hall_lv_04 | G7: to_gold | H7: 800 | I7: 2 | J7: item | K7: to_ticketrare | L7: 5 | Q7: item | R7: to_gold | S7: 150000
A8: =C8&"_level_"&D8 -> s1_level_5 | B8: lbh9517_175126 | C8: s1 | D8: 5 | E8: bg_nexus1_50pct | F8: nexus_hall_lv_05 | G8: to_gold | H8: 1250 | I8: 3 | J8: node | K8: to_gold | L8: 100000 | Q8: item | R8: to_powder | S8: 30
A9: =C9&"_level_"&D9 -> s1_level_6 | B9: lbh9517_175126 | C9: s1 | D9: 6 | E9: bg_nexus1_50pct | F9: nexus_hall_lv_06 | G9: to_gold | H9: 1800 | I9: 3 | J9: item | K9: to_ticketrare_wish | L9: 5 | Q9: item | R9: to_stigma | S9: 400
A10: =C10&"_level_"&D10 -> s1_level_7 | B10: lbh9517_175126 | C10: s1 | D10: 7 | E10: bg_nexus1_75pct | F10: nexus_hall_lv_07 | G10: to_gold | H10: 2450 | I10: 4 | J10: node | K10: to_gold | L10: 100000 | Q10: item | R10: to_ticketspecial | S10: 30
A11: =C11&"_level_"&D11 -> s1_level_8 | B11: lbh9517_175126 | C11: s1 | D11: 8 | E11: bg_nexus1_75pct | F11: nexus_hall_lv_08 | G11: to_gold | H11: 3200 | I11: 4 | J11: item | K11: to_crystal | L11: 150 | Q11: item | R11: to_powder | S11: 60
A12: =C12&"_level_"&D12 -> s1_level_9 | B12: lbh9517_175126 | C12: s1 | D12: 9 | E12: bg_nexus1_100pct | F12: nexus_hall_lv_09 | G12: to_gold | H12: 4050 | I12: 5 | J12: node | K12: to_gold | L12: 100000 | Q12: item | R12: to_mura | S12: 2
A13: =C13&"_level_"&D13 -> s1_level_10 | B13: lbh9517_175126 | C13: s1 | D13: 10 | E13: bg_nexus1_100pct | F13: nexus_hall_lv_10 | G13: to_gold | H13: 5000 | I13: 5 | J13: item | K13: to_ticketmoon | L13: 5 | Q13: item | R13: sp_eqf5s_210422 | S13: 1

Sheet nexus_node_category
A1: lbh9517_175126 | B1: lbh9517_175126 | E1: lbh9517_175126 | F1: lbh9517_175126
A2: 노드카테고리id | C2: 테마 id 주석 | D2: 노드 카테고리 주석 | E2: 카테고리 정렬 순서 | F2: 노드 이름 tid
A3: category | B3: export_id | E3: index | F3: node_name
A4: =_xlfn.TEXTJOIN("_",TRUE,C4,D4) -> survival | B4: lbh9517_175126 | D4: survival | E4: 1 | F4: ="s1_node_"&D4&"_name" -> s1_node_survival_name
A5: =_xlfn.TEXTJOIN("_",TRUE,C5,D5) -> economy | B5: lbh9517_175126 | D5: economy | E5: 2 | F5: ="s1_node_"&D5&"_name" -> s1_node_economy_name
A6: =_xlfn.TEXTJOIN("_",TRUE,C6,D6) -> recruit | B6: lbh9517_175126 | D6: recruit | E6: 3 | F6: ="s1_node_"&D6&"_name" -> s1_node_recruit_name
A7: =_xlfn.TEXTJOIN("_",TRUE,C7,D7) -> relic | B7: lbh9517_175126 | D7: relic | E7: 4 | F7: ="s1_node_"&D7&"_name" -> s1_node_relic_name
A8: =_xlfn.TEXTJOIN("_",TRUE,C8,D8) -> battle | B8: lbh9517_175126 | D8: battle | E8: 5 | F8: ="s1_node_"&D8&"_name" -> s1_node_battle_name
A9: =_xlfn.TEXTJOIN("_",TRUE,C9,D9) -> archive | B9: lbh9517_175126 | D9: archive | E9: 6 | F9: ="s1_node_"&D9&"_name" -> s1_node_archive_name

Sheet nexus_node
A1: lbh9517_175126 | B1: lbh9517_175126 | C1: lbh9517_175126 | D1: lbh9517_175126 | E1: lbh9517_175126 | F1: lbh9517_175126 | G1: lbh9517_175126 | H1: lbh9517_175126 | I1: lbh9517_175126 | J1: lbh9517_175126 | L1: lbh9517_175126 | M1: lbh9517_175126 | N1: lbh9517_175126 | O1: lbh9517_175126 | P1: lbh9517_175126 | Q1: lbh9517_175126 | R1: lbh9517_175126 | S1: lbh9517_175126 | T1: lbh9517_175126
A2: 고유값 | C2: 테마 id | D2: 노드 카테고리 | E2: 카테고리 TID | F2: 카테고리 TID | G2: 노드 이미지 파일명 | H2: 메인 리워드 권한 | I2: 노드 활성화 필요 아이템 | J2: 노드 활성화 필요 개수 | K2: 전체 필요 개수 | L2: 노드 활성화 횟수 | M2: 노드 칼럼 위치 | N2: 노드 행 위치 | O2: 선행 조건 노드 ID 1 | P2: 선행 조건 노드 ID 2 | Q2: 선행 조건 노드 ID 3 | R2: 선행 조건 노드 ID 4 | S2: 선행 조건 노드 ID 5 | T2: nexus_effect 테이블의 id 입력
A3: id | B3: export_id | C3: theme_id | D3: category | E3: category_name | F3: node_effect_desc | G3: image | H3: node_permission | I3: active_item_id | J3: active_item_value | L3: active_step | M3: column | N3: row | O3: condition_node_1 | P3: condition_node_2 | Q3: condition_node_3 | R3: condition_node_4 | S3: condition_node_5 | T3: nexus_effect_id
A4: =_xlfn.TEXTJOIN("_",TRUE,C4,"node",D4,M4,N4) -> s1_node_survival_1_4 | B4: lbh9517_175126 | C4: s1 | D4: survival | E4: ="s1_node_"&D4&"_name" -> s1_node_survival_name | F4: ="s1_node_"&D4&"_desc" -> s1_node_survival_desc | G4: icon_menu_max_hp | H4: 1 | I4: to_gold | J4: 20;30;30 | K4: 80 | L4: 3 | M4: 1 | N4: 4 | T4: =_xlfn.TEXTJOIN("_",TRUE,C4,"node_eff",D4,M4,N4) -> s1_node_eff_survival_1_4
A5: =_xlfn.TEXTJOIN("_",TRUE,C5,"node",D5,M5,N5) -> s1_node_survival_2_2 | B5: lbh9517_175126 | C5: s1 | D5: survival | E5: ="s1_node_"&D5&"_name" -> s1_node_survival_name | F5: ="s1_node_"&D5&"_desc" -> s1_node_survival_desc | G5: icon_menu_max_hp | H5: 1 | I5: to_gold | J5: 30;40;50 | K5: 120 | L5: 3 | M5: 2 | N5: 2 | O5: s1_node_survival_1_4 | T5: =_xlfn.TEXTJOIN("_",TRUE,C5,"node_eff",D5,M5,N5) -> s1_node_eff_survival_2_2
A6: =_xlfn.TEXTJOIN("_",TRUE,C6,"node",D6,M6,N6) -> s1_node_survival_2_6 | B6: lbh9517_175126 | C6: s1 | D6: survival | E6: ="s1_node_"&D6&"_name" -> s1_node_survival_name | F6: ="s1_node_"&D6&"_desc" -> s1_node_survival_desc | G6: icon_menu_trust | H6: 1 | I6: to_gold | J6: 30;40;50 | K6: 120 | L6: 3 | M6: 2 | N6: 6 | O6: s1_node_survival_1_4 | T6: =_xlfn.TEXTJOIN("_",TRUE,C6,"node_eff",D6,M6,N6) -> s1_node_eff_survival_2_6
A7: =_xlfn.TEXTJOIN("_",TRUE,C7,"node",D7,M7,N7) -> s1_node_survival_3_2 | B7: lbh9517_175126 | C7: s1 | D7: survival | E7: ="s1_node_"&D7&"_name" -> s1_node_survival_name | F7: ="s1_node_"&D7&"_desc" -> s1_node_survival_desc | G7: icon_menu_trust | H7: 1 | I7: to_gold | J7: 40;50;60 | K7: 150 | L7: 3 | M7: 3 | N7: 2 | O7: s1_node_survival_2_2 | T7: =_xlfn.TEXTJOIN("_",TRUE,C7,"node_eff",D7,M7,N7) -> s1_node_eff_survival_3_2
A8: =_xlfn.TEXTJOIN("_",TRUE,C8,"node",D8,M8,N8) -> s1_node_survival_3_6 | B8: lbh9517_175126 | C8: s1 | D8: survival | E8: ="s1_node_"&D8&"_name" -> s1_node_survival_name | F8: ="s1_node_"&D8&"_desc" -> s1_node_survival_desc | G8: icon_menu_max_hp | H8: 1 | I8: to_gold | J8: 40;50;60 | K8: 150 | L8: 3 | M8: 3 | N8: 6 | O8: s1_node_survival_2_6 | T8: =_xlfn.TEXTJOIN("_",TRUE,C8,"node_eff",D8,M8,N8) -> s1_node_eff_survival_3_6
A9: =_xlfn.TEXTJOIN("_",TRUE,C9,"node",D9,M9,N9) -> s1_node_survival_4_2 | B9: lbh9517_175126 | C9: s1 | D9: survival | E9: ="s1_node_"&D9&"_name" -> s1_node_survival_name | F9: ="s1_node_"&D9&"_desc" -> s1_node_survival_desc | G9: icon_menu_max_hp | H9: 1 | I9: to_gold | J9: 50;60;70 | K9: 180 | L9: 3 | M9: 4 | N9: 2 | O9: s1_node_survival_3_2 | T9: =_xlfn.TEXTJOIN("_",TRUE,C9,"node_eff",D9,M9,N9) -> s1_node_eff_survival_4_2
A10: =_xlfn.TEXTJOIN("_",TRUE,C10,"node",D10,M10,N10) -> s1_node_survival_4_6 | B10: lbh9517_175126 | C10: s1 | D10: survival | E10: ="s1_node_"&D10&"_name" -> s1_node_survival_name | F10: ="s1_node_"&D10&"_desc" -> s1_node_survival_desc | G10: icon_menu_max_hp | H10: 1 | I10: to_gold | J10: 50;60;70 | K10: 180 | L10: 3 | M10: 4 | N10: 6 | O10: s1_node_survival_3_6 | T10: =_xlfn.TEXTJOIN("_",TRUE,C10,"node_eff",D10,M10,N10) -> s1_node_eff_survival_4_6
A11: =_xlfn.TEXTJOIN("_",TRUE,C11,"node",D11,M11,N11) -> s1_node_survival_5_2 | B11: lbh9517_175126 | C11: s1 | D11: survival | E11: ="s1_node_"&D11&"_name" -> s1_node_survival_name | F11: ="s1_node_"&D11&"_desc" -> s1_node_survival_desc | G11: icon_menu_battle2 | H11: 1 | I11: to_gold | J11: 60;70;90 | K11: 220 | L11: 3 | M11: 5 | N11: 2 | O11: s1_node_survival_4_2 | T11: =_xlfn.TEXTJOIN("_",TRUE,C11,"node_eff",D11,M11,N11) -> s1_node_eff_survival_5_2
A12: =_xlfn.TEXTJOIN("_",TRUE,C12,"node",D12,M12,N12) -> s1_node_survival_5_6 | B12: lbh9517_175126 | C12: s1 | D12: survival | E12: ="s1_node_"&D12&"_name" -> s1_node_survival_name | F12: ="s1_node_"&D12&"_desc" -> s1_node_survival_desc | G12: icon_menu_battle2 | H12: 1 | I12: to_gold | J12: 60;70;90 | K12: 220 | L12: 3 | M12: 5 | N12: 6 | O12: s1_node_survival_4_6 | T12: =_xlfn.TEXTJOIN("_",TRUE,C12,"node_eff",D12,M12,N12) -> s1_node_eff_survival_5_6
A13: =_xlfn.TEXTJOIN("_",TRUE,C13,"node",D13,M13,N13) -> s1_node_survival_6_4 | B13: lbh9517_175126 | C13: s1 | D13: survival | E13: ="s1_node_"&D13&"_name" -> s1_node_survival_name | F13: ="s1_node_"&D13&"_desc" -> s1_node_survival_desc | G13: icon_menu_max_hp | H13: 1 | I13: to_gold | J13: 70;80;100 | K13: 250 | L13: 3 | M13: 6 | N13: 4 | O13: s1_node_survival_5_2 | P13: s1_node_survival_5_6 | T13: =_xlfn.TEXTJOIN("_",TRUE,C13,"node_eff",D13,M13,N13) -> s1_node_eff_survival_6_4
A14: =_xlfn.TEXTJOIN("_",TRUE,C14,"node",D14,M14,N14) -> s1_node_survival_7_2 | B14: lbh9517_175126 | C14: s1 | D14: survival | E14: ="s1_node_"&D14&"_name" -> s1_node_survival_name | F14: ="s1_node_"&D14&"_desc" -> s1_node_survival_desc | G14: icon_menu_max_hp | H14: 1 | I14: to_gold | J14: 90;100;100 | K14: 290 | L14: 3 | M14: 7 | N14: 2 | O14: s1_node_survival_6_4 | T14: =_xlfn.TEXTJOIN("_",TRUE,C14,"node_eff",D14,M14,N14) -> s1_node_eff_survival_7_2
A15: =_xlfn.TEXTJOIN("_",TRUE,C15,"node",D15,M15,N15) -> s1_node_survival_7_6 | B15: lbh9517_175126 | C15: s1 | D15: survival | E15: ="s1_node_"&D15&"_name" -> s1_node_survival_name | F15: ="s1_node_"&D15&"_desc" -> s1_node_survival_desc | G15: icon_menu_trust | H15: 1 | I15: to_gold | J15: 90;100;100 | K15: 290 | L15: 3 | M15: 7 | N15: 6 | O15: s1_node_survival_6_4 | T15: =_xlfn.TEXTJOIN("_",TRUE,C15,"node_eff",D15,M15,N15) -> s1_node_eff_survival_7_6
A16: =_xlfn.TEXTJOIN("_",TRUE,C16,"node",D16,M16,N16) -> s1_node_survival_8_2 | B16: lbh9517_175126 | C16: s1 | D16: survival | E16: ="s1_node_"&D16&"_name" -> s1_node_survival_name | F16: ="s1_node_"&D16&"_desc" -> s1_node_survival_desc | G16: icon_menu_trust | H16: 1 | I16: to_gold | J16: 100;110;110 | K16: 320 | L16: 3 | M16: 8 | N16: 2 | O16: s1_node_survival_7_2 | T16: =_xlfn.TEXTJOIN("_",TRUE,C16,"node_eff",D16,M16,N16) -> s1_node_eff_survival_8_2
A17: =_xlfn.TEXTJOIN("_",TRUE,C17,"node",D17,M17,N17) -> s1_node_survival_8_6 | B17: lbh9517_175126 | C17: s1 | D17: survival | E17: ="s1_node_"&D17&"_name" -> s1_node_survival_name | F17: ="s1_node_"&D17&"_desc" -> s1_node_survival_desc | G17: icon_menu_max_hp | H17: 1 | I17: to_gold | J17: 100;110;110 | K17: 320 | L17: 3 | M17: 8 | N17: 6 | O17: s1_node_survival_7_6 | T17: =_xlfn.TEXTJOIN("_",TRUE,C17,"node_eff",D17,M17,N17) -> s1_node_eff_survival_8_6
A18: =_xlfn.TEXTJOIN("_",TRUE,C18,"node",D18,M18,N18) -> s1_node_survival_9_2 | B18: lbh9517_175126 | C18: s1 | D18: survival | E18: ="s1_node_"&D18&"_name" -> s1_node_survival_name | F18: ="s1_node_"&D18&"_desc" -> s1_node_survival_desc | G18: icon_menu_max_hp | H18: 1 | I18: to_gold | J18: 110;120;130 | K18: 360 | L18: 3 | M18: 9 | N18: 2 | O18: s1_node_survival_8_2 | T18: =_xlfn.TEXTJOIN("_",TRUE,C18,"node_eff",D18,M18,N18) -> s1_node_eff_survival_9_2
A19: =_xlfn.TEXTJOIN("_",TRUE,C19,"node",D19,M19,N19) -> s1_node_survival_9_6 | B19: lbh9517_175126 | C19: s1 | D19: survival | E19: ="s1_node_"&D19&"_name" -> s1_node_survival_name | F19: ="s1_node_"&D19&"_desc" -> s1_node_survival_desc | G19: icon_menu_max_hp | H19: 1 | I19: to_gold | J19: 110;120;130 | K19: 360 | L19: 3 | M19: 9 | N19: 6 | O19: s1_node_survival_8_6 | T19: =_xlfn.TEXTJOIN("_",TRUE,C19,"node_eff",D19,M19,N19) -> s1_node_eff_survival_9_6
A20: =_xlfn.TEXTJOIN("_",TRUE,C20,"node",D20,M20,N20) -> s1_node_survival_10_2 | B20: lbh9517_175126 | C20: s1 | D20: survival | E20: ="s1_node_"&D20&"_name" -> s1_node_survival_name | F20: ="s1_node_"&D20&"_desc" -> s1_node_survival_desc | G20: icon_menu_battle2 | H20: 1 | I20: to_gold | J20: 120;130;140 | K20: 390 | L20: 3 | M20: 10 | N20: 2 | O20: s1_node_survival_9_2 | T20: =_xlfn.TEXTJOIN("_",TRUE,C20,"node_eff",D20,M20,N20) -> s1_node_eff_survival_10_2
A21: =_xlfn.TEXTJOIN("_",TRUE,C21,"node",D21,M21,N21) -> s1_node_survival_10_6 | B21: lbh9517_175126 | C21: s1 | D21: survival | E21: ="s1_node_"&D21&"_name" -> s1_node_survival_name | F21: ="s1_node_"&D21&"_desc" -> s1_node_survival_desc | G21: icon_menu_battle2 | H21: 1 | I21: to_gold | J21: 120;130;140 | K21: 390 | L21: 3 | M21: 10 | N21: 6 | O21: s1_node_survival_9_6 | T21: =_xlfn.TEXTJOIN("_",TRUE,C21,"node_eff",D21,M21,N21) -> s1_node_eff_survival_10_6
A22: =_xlfn.TEXTJOIN("_",TRUE,C22,"node",D22,M22,N22) -> s1_node_survival_11_4 | B22: lbh9517_175126 | C22: s1 | D22: survival | E22: ="s1_node_"&D22&"_name" -> s1_node_survival_name | F22: ="s1_node_"&D22&"_desc" -> s1_node_survival_desc | G22: icon_menu_max_hp | H22: 1 | I22: to_gold | J22: 130;140;160 | K22: 430 | L22: 3 | M22: 11 | N22: 4 | O22: s1_node_survival_10_2 | P22: s1_node_survival_10_6 | T22: =_xlfn.TEXTJOIN("_",TRUE,C22,"node_eff",D22,M22,N22) -> s1_node_eff_survival_11_4
A23: =_xlfn.TEXTJOIN("_",TRUE,C23,"node",D23,M23,N23) -> s1_node_survival_12_2 | B23: lbh9517_175126 | C23: s1 | D23: survival | E23: ="s1_node_"&D23&"_name" -> s1_node_survival_name | F23: ="s1_node_"&D23&"_desc" -> s1_node_survival_desc | G23: icon_menu_max_hp | H23: 1 | I23: to_gold | J23: 140;150;170 | K23: 460 | L23: 3 | M23: 12 | N23: 2 | O23: s1_node_survival_11_4 | T23: =_xlfn.TEXTJOIN("_",TRUE,C23,"node_eff",D23,M23,N23) -> s1_node_eff_survival_12_2
A24: =_xlfn.TEXTJOIN("_",TRUE,C24,"node",D24,M24,N24) -> s1_node_survival_12_6 | B24: lbh9517_175126 | C24: s1 | D24: survival | E24: ="s1_node_"&D24&"_name" -> s1_node_survival_name | F24: ="s1_node_"&D24&"_desc" -> s1_node_survival_desc | G24: icon_menu_trust | H24: 1 | I24: to_gold | J24: 140;150;170 | K24: 460 | L24: 3 | M24: 12 | N24: 6 | O24: s1_node_survival_11_4 | T24: =_xlfn.TEXTJOIN("_",TRUE,C24,"node_eff",D24,M24,N24) -> s1_node_eff_survival_12_6
A25: =_xlfn.TEXTJOIN("_",TRUE,C25,"node",D25,M25,N25) -> s1_node_survival_13_2 | B25: lbh9517_175126 | C25: s1 | D25: survival | E25: ="s1_node_"&D25&"_name" -> s1_node_survival_name | F25: ="s1_node_"&D25&"_desc" -> s1_node_survival_desc | G25: icon_menu_trust | H25: 1 | I25: to_gold | J25: 160;170;170 | K25: 500 | L25: 3 | M25: 13 | N25: 2 | O25: s1_node_survival_12_2 | T25: =_xlfn.TEXTJOIN("_",TRUE,C25,"node_eff",D25,M25,N25) -> s1_node_eff_survival_13_2
A26: =_xlfn.TEXTJOIN("_",TRUE,C26,"node",D26,M26,N26) -> s1_node_survival_13_6 | B26: lbh9517_175126 | C26: s1 | D26: survival | E26: ="s1_node_"&D26&"_name" -> s1_node_survival_name | F26: ="s1_node_"&D26&"_desc" -> s1_node_survival_desc | G26: icon_menu_max_hp | H26: 1 | I26: to_gold | J26: 160;170;170 | K26: 500 | L26: 3 | M26: 13 | N26: 6 | O26: s1_node_survival_12_6 | T26: =_xlfn.TEXTJOIN("_",TRUE,C26,"node_eff",D26,M26,N26) -> s1_node_eff_survival_13_6
A27: =_xlfn.TEXTJOIN("_",TRUE,C27,"node",D27,M27,N27) -> s1_node_survival_14_2 | B27: lbh9517_175126 | C27: s1 | D27: survival | E27: ="s1_node_"&D27&"_name" -> s1_node_survival_name | F27: ="s1_node_"&D27&"_desc" -> s1_node_survival_desc | G27: icon_menu_max_hp | H27: 1 | I27: to_gold | J27: 170;180;180 | K27: 530 | L27: 3 | M27: 14 | N27: 2 | O27: s1_node_survival_13_2 | T27: =_xlfn.TEXTJOIN("_",TRUE,C27,"node_eff",D27,M27,N27) -> s1_node_eff_survival_14_2
A28: =_xlfn.TEXTJOIN("_",TRUE,C28,"node",D28,M28,N28) -> s1_node_survival_14_6 | B28: lbh9517_175126 | C28: s1 | D28: survival | E28: ="s1_node_"&D28&"_name" -> s1_node_survival_name | F28: ="s1_node_"&D28&"_desc" -> s1_node_survival_desc | G28: icon_menu_max_hp | H28: 1 | I28: to_gold | J28: 170;180;180 | K28: 530 | L28: 3 | M28: 14 | N28: 6 | O28: s1_node_survival_13_6 | T28: =_xlfn.TEXTJOIN("_",TRUE,C28,"node_eff",D28,M28,N28) -> s1_node_eff_survival_14_6
A29: =_xlfn.TEXTJOIN("_",TRUE,C29,"node",D29,M29,N29) -> s1_node_survival_15_2 | B29: lbh9517_175126 | C29: s1 | D29: survival | E29: ="s1_node_"&D29&"_name" -> s1_node_survival_name | F29: ="s1_node_"&D29&"_desc" -> s1_node_survival_desc | G29: icon_menu_battle2 | H29: 1 | I29: to_gold | J29: 180;190;200 | K29: 570 | L29: 3 | M29: 15 | N29: 2 | O29: s1_node_survival_14_2 | T29: =_xlfn.TEXTJOIN("_",TRUE,C29,"node_eff",D29,M29,N29) -> s1_node_eff_survival_15_2
A30: =_xlfn.TEXTJOIN("_",TRUE,C30,"node",D30,M30,N30) -> s1_node_survival_15_6 | B30: lbh9517_175126 | C30: s1 | D30: survival | E30: ="s1_node_"&D30&"_name" -> s1_node_survival_name | F30: ="s1_node_"&D30&"_desc" -> s1_node_survival_desc | G30: icon_menu_battle2 | H30: 1 | I30: to_gold | J30: 180;190;200 | K30: 570 | L30: 3 | M30: 15 | N30: 6 | O30: s1_node_survival_14_6 | T30: =_xlfn.TEXTJOIN("_",TRUE,C30,"node_eff",D30,M30,N30) -> s1_node_eff_survival_15_6
A31: =_xlfn.TEXTJOIN("_",TRUE,C31,"node",D31,M31,N31) -> s1_node_survival_16_4 | B31: lbh9517_175126 | C31: s1 | D31: survival | E31: ="s1_node_"&D31&"_name" -> s1_node_survival_name | F31: ="s1_node_"&D31&"_desc" -> s1_node_survival_desc | G31: icon_menu_max_hp | H31: 1 | I31: to_gold | J31: 190;200;210 | K31: 600 | L31: 3 | M31: 16 | N31: 4 | O31: s1_node_survival_15_2 | P31: s1_node_survival_15_6 | T31: =_xlfn.TEXTJOIN("_",TRUE,C31,"node_eff",D31,M31,N31) -> s1_node_eff_survival_16_4
A32: =_xlfn.TEXTJOIN("_",TRUE,C32,"node",D32,M32,N32) -> s1_node_survival_17_2 | B32: lbh9517_175126 | C32: s1 | D32: survival | E32: ="s1_node_"&D32&"_name" -> s1_node_survival_name | F32: ="s1_node_"&D32&"_desc" -> s1_node_survival_desc | G32: icon_menu_max_hp | H32: 1 | I32: to_gold | J32: 200;210;230 | K32: 640 | L32: 3 | M32: 17 | N32: 2 | O32: s1_node_survival_16_4 | T32: =_xlfn.TEXTJOIN("_",TRUE,C32,"node_eff",D32,M32,N32) -> s1_node_eff_survival_17_2
A33: =_xlfn.TEXTJOIN("_",TRUE,C33,"node",D33,M33,N33) -> s1_node_survival_17_6 | B33: lbh9517_175126 | C33: s1 | D33: survival | E33: ="s1_node_"&D33&"_name" -> s1_node_survival_name | F33: ="s1_node_"&D33&"_desc" -> s1_node_survival_desc | G33: icon_menu_trust | H33: 1 | I33: to_gold | J33: 200;210;230 | K33: 640 | L33: 3 | M33: 17 | N33: 6 | O33: s1_node_survival_16_4 | T33: =_xlfn.TEXTJOIN("_",TRUE,C33,"node_eff",D33,M33,N33) -> s1_node_eff_survival_17_6
A34: =_xlfn.TEXTJOIN("_",TRUE,C34,"node",D34,M34,N34) -> s1_node_survival_18_2 | B34: lbh9517_175126 | C34: s1 | D34: survival | E34: ="s1_node_"&D34&"_name" -> s1_node_survival_name | F34: ="s1_node_"&D34&"_desc" -> s1_node_survival_desc | G34: icon_menu_trust | H34: 1 | I34: to_gold | J34: 210;220;240 | K34: 670 | L34: 3 | M34: 18 | N34: 2 | O34: s1_node_survival_17_2 | T34: =_xlfn.TEXTJOIN("_",TRUE,C34,"node_eff",D34,M34,N34) -> s1_node_eff_survival_18_2
A35: =_xlfn.TEXTJOIN("_",TRUE,C35,"node",D35,M35,N35) -> s1_node_survival_18_6 | B35: lbh9517_175126 | C35: s1 | D35: survival | E35: ="s1_node_"&D35&"_name" -> s1_node_survival_name | F35: ="s1_node_"&D35&"_desc" -> s1_node_survival_desc | G35: icon_menu_max_hp | H35: 1 | I35: to_gold | J35: 210;220;240 | K35: 670 | L35: 3 | M35: 18 | N35: 6 | O35: s1_node_survival_17_6 | T35: =_xlfn.TEXTJOIN("_",TRUE,C35,"node_eff",D35,M35,N35) -> s1_node_eff_survival_18_6
A36: =_xlfn.TEXTJOIN("_",TRUE,C36,"node",D36,M36,N36) -> s1_node_survival_19_2 | B36: lbh9517_175126 | C36: s1 | D36: survival | E36: ="s1_node_"&D36&"_name" -> s1_node_survival_name | F36: ="s1_node_"&D36&"_desc" -> s1_node_survival_desc | G36: icon_menu_max_hp | H36: 1 | I36: to_gold | J36: 230;240;240 | K36: 710 | L36: 3 | M36: 19 | N36: 2 | O36: s1_node_survival_18_2 | T36: =_xlfn.TEXTJOIN("_",TRUE,C36,"node_eff",D36,M36,N36) -> s1_node_eff_survival_19_2
A37: =_xlfn.TEXTJOIN("_",TRUE,C37,"node",D37,M37,N37) -> s1_node_survival_19_6 | B37: lbh9517_175126 | C37: s1 | D37: survival | E37: ="s1_node_"&D37&"_name" -> s1_node_survival_name | F37: ="s1_node_"&D37&"_desc" -> s1_node_survival_desc | G37: icon_menu_max_hp | H37: 1 | I37: to_gold | J37: 230;240;240 | K37: 710 | L37: 3 | M37: 19 | N37: 6 | O37: s1_node_survival_18_6 | T37: =_xlfn.TEXTJOIN("_",TRUE,C37,"node_eff",D37,M37,N37) -> s1_node_eff_survival_19_6
A38: =_xlfn.TEXTJOIN("_",TRUE,C38,"node",D38,M38,N38) -> s1_node_survival_20_2 | B38: lbh9517_175126 | C38: s1 | D38: survival | E38: ="s1_node_"&D38&"_name" -> s1_node_survival_name | F38: ="s1_node_"&D38&"_desc" -> s1_node_survival_desc | G38: icon_menu_battle2 | H38: 1 | I38: to_gold | J38: 240;250;250 | K38: 740 | L38: 3 | M38: 20 | N38: 2 | O38: s1_node_survival_19_2 | T38: =_xlfn.TEXTJOIN("_",TRUE,C38,"node_eff",D38,M38,N38) -> s1_node_eff_survival_20_2
A39: =_xlfn.TEXTJOIN("_",TRUE,C39,"node",D39,M39,N39) -> s1_node_survival_20_6 | B39: lbh9517_175126 | C39: s1 | D39: survival | E39: ="s1_node_"&D39&"_name" -> s1_node_survival_name | F39: ="s1_node_"&D39&"_desc" -> s1_node_survival_desc | G39: icon_menu_battle2 | H39: 1 | I39: to_gold | J39: 240;250;250 | K39: 740 | L39: 3 | M39: 20 | N39: 6 | O39: s1_node_survival_19_6 | T39: =_xlfn.TEXTJOIN("_",TRUE,C39,"node_eff",D39,M39,N39) -> s1_node_eff_survival_20_6
A40: =_xlfn.TEXTJOIN("_",TRUE,C40,"node",D40,M40,N40) -> s1_node_survival_21_4 | B40: lbh9517_175126 | C40: s1 | D40: survival | E40: ="s1_node_"&D40&"_name" -> s1_node_survival_name | F40: ="s1_node_"&D40&"_desc" -> s1_node_survival_desc | G40: icon_menu_max_hp | H40: 2 | I40: to_gold | J40: 250;260;270 | K40: 780 | L40: 3 | M40: 21 | N40: 4 | O40: s1_node_survival_20_2 | P40: s1_node_survival_20_6 | T40: =_xlfn.TEXTJOIN("_",TRUE,C40,"node_eff",D40,M40,N40) -> s1_node_eff_survival_21_4
...

Sheet nexus_dic_story
A1: lbh9517_175126 | B1: lbh9517_175126 | C1: lbh9517_175126 | D1: lbh9517_175126 | E1: lbh9517_175126
A2: 고유값 | C2: 테마 id | D2: 표시 순서 | E2: 서브스토리 DB id
A3: id | B3: export_id | C3: theme_id | D3: index | E3: story_id
A4: =_xlfn.TEXTJOIN("_",TRUE,C4,"dic_story",D4) -> s1_dic_story_1 | B4: lbh9517_175126 | C4: s1 | D4: 1 | E4: v5154a_002_1
A5: =_xlfn.TEXTJOIN("_",TRUE,C5,"dic_story",D5) -> s1_dic_story_2 | B5: lbh9517_175126 | C5: s1 | D5: 2 | E5: v5154a_002_2
A6: =_xlfn.TEXTJOIN("_",TRUE,C6,"dic_story",D6) -> s1_dic_story_3 | B6: lbh9517_175126 | C6: s1 | D6: 3 | E6: v5154a_002_3
A7: =_xlfn.TEXTJOIN("_",TRUE,C7,"dic_story",D7) -> s1_dic_story_4 | B7: lbh9517_175126 | C7: s1 | D7: 4 | E7: v5154a_002_4
A8: =_xlfn.TEXTJOIN("_",TRUE,C8,"dic_story",D8) -> s1_dic_story_5 | B8: lbh9517_175126 | C8: s1 | D8: 5 | E8: v5154a_002_5
A9: =_xlfn.TEXTJOIN("_",TRUE,C9,"dic_story",D9) -> s1_dic_story_6 | B9: lbh9517_175126 | C9: s1 | D9: 6 | E9: v5154a_002_6
A10: =_xlfn.TEXTJOIN("_",TRUE,C10,"dic_story",D10) -> s1_dic_story_7 | B10: lbh9517_175126 | C10: s1 | D10: 7 | E10: v5154a_002_7
A11: =_xlfn.TEXTJOIN("_",TRUE,C11,"dic_story",D11) -> s1_dic_story_8 | B11: lbh9517_175126 | C11: s1 | D11: 8 | E11: v5154a_002_8
A12: =_xlfn.TEXTJOIN("_",TRUE,C12,"dic_story",D12) -> s1_dic_story_9 | B12: lbh9517_175126 | C12: s1 | D12: 9 | E12: v5154a_002_9
A13: =_xlfn.TEXTJOIN("_",TRUE,C13,"dic_story",D13) -> s1_dic_story_10 | B13: lbh9517_175126 | C13: s1 | D13: 10 | E13: v5154a_002_10
A14: =_xlfn.TEXTJOIN("_",TRUE,C14,"dic_story",D14) -> s1_dic_story_11 | B14: lbh9517_175126 | C14: s1 | D14: 11 | E14: v5154a_002_11
A15: =_xlfn.TEXTJOIN("_",TRUE,C15,"dic_story",D15) -> s1_dic_story_12 | B15: lbh9517_175126 | C15: s1 | D15: 12 | E15: v5154a_002_12
... A18: =_xlfn.TEXTJOIN("_",TRUE,C18,"dic_story",D18) -> s1_dic_story_15 | B18: lbh9517_175126 | C18: s1 | D18: 15 | E18: v5154a_002_15

Sheet nexus_dic_event
A1: lbh9517_175126 | B1: lbh9517_175126 | C1: lbh9517_175126 | D1: lbh9517_175126 | E1: lbh9517_175126 | F1: lbh9517_175126 | G1: lbh9517_175126
A2: 고유값 | C2: 테마 id | D2: 카테고리 | E2: 표시 순서 | F2: 타이틀 TID | G2: 설명 TID
A3: id | B3: export_id | C3: theme_id | D3: category | E3: index | F3: event_title | G3: event_desc
A4: =_xlfn.TEXTJOIN("_",TRUE,C4,"dic",D4,E4) -> s1_dic_event_1_1 | B4: lbh9517_175126 | C4: s1 | D4: event_1 | E4: 1 | F4: 낡은 유물함 | G4: 먼지 쌓인 유물함을 회수하거나 그냥 지나치는 사건.
A5: =_xlfn.TEXTJOIN("_",TRUE,C5,"dic",D5,E5) -> s1_dic_event_1_2 | B5: lbh9517_175126 | C5: s1 | D5: event_1 | E5: 2 | F5: 별빛 파편 상자 | G5: 차원 파편이 담긴 상자에서 유물 또는 재화를 노린다.
A6: =_xlfn.TEXTJOIN("_",TRUE,C6,"dic",D6,E6) -> s1_dic_event_1_3 | B6: lbh9517_175126 | C6: s1 | D6: event_1 | E6: 3 | F6: 기억의 진열대 | G6: 기록 아카이브 단서와 탐사 보상을 교환하는 사건.
A7: =_xlfn.TEXTJOIN("_",TRUE,C7,"dic",D7,E7) -> s1_dic_event_1_4 | B7: lbh9517_175126 | C7: s1 | D7: event_1 | E7: 4 | F7: 수호자의 전리품 | G7: 수호자의 흔적에서 전투 보상 또는 유물을 회수한다.
A8: =_xlfn.TEXTJOIN("_",TRUE,C8,"dic",D8,E8) -> s1_dic_event_1_5 | B8: lbh9517_175126 | C8: s1 | D8: event_1 | E8: 5 | F8: 속삭이는 기록관 | G8: 도감 단서를 얻는 대신 탐사 자원을 소모한다.
A9: =_xlfn.TEXTJOIN("_",TRUE,C9,"dic",D9,E9) -> s1_dic_event_1_6 | B9: lbh9517_175126 | C9: s1 | D9: event_1 | E9: 6 | F9: 봉인된 보관함 | G9: 봉인을 해제해 보상을 얻거나 실패 위험을 감수한다.
A10: =_xlfn.TEXTJOIN("_",TRUE,C10,"dic",D10,E10) -> s1_dic_event_1_7 | B10: lbh9517_175126 | C10: s1 | D10: event_1 | E10: 7 | F10: 탐험가의 선반 | G10: 이전 탐험가가 남긴 소모품과 정보를 선택한다.
A11: =_xlfn.TEXTJOIN("_",TRUE,C11,"dic",D11,E11) -> s1_dic_event_2_1 | B11: lbh9517_175126 | C11: s1 | D11: event_2 | E11: 1 | F11: 결투의 잔상 | G11: 다른 탐사대의 환영과 영웅 대 영웅 전투를 벌인다.
A12: =_xlfn.TEXTJOIN("_",TRUE,C12,"dic",D12,E12) -> s1_dic_event_2_2 | B12: lbh9517_175126 | C12: s1 | D12: event_2 | E12: 2 | F12: 균열 검투사 | G12: 균열에 남은 투사의 기록을 상대하고 보상을 획득한다.
A13: =_xlfn.TEXTJOIN("_",TRUE,C13,"dic",D13,E13) -> s1_dic_event_2_3 | B13: lbh9517_175126 | C13: s1 | D13: event_2 | E13: 3 | F13: 차원 투기장 | G13: 제한 조건이 붙은 PvP식 전투를 선택할 수 있다.
A14: =_xlfn.TEXTJOIN("_",TRUE,C14,"dic",D14,E14) -> s1_dic_event_2_4 | B14: lbh9517_175126 | C14: s1 | D14: event_2 | E14: 4 | F14: 이름 없는 도전자 | G14: 무작위 조합의 적 영웅 파티와 교전한다.
A15: =_xlfn.TEXTJOIN("_",TRUE,C15,"dic",D15,E15) -> s1_dic_event_2_5 | B15: lbh9517_175126 | C15: s1 | D15: event_2 | E15: 5 | F15: 전술 모의전 | G15: 태그와 영입 구성을 시험하는 모의 전투 사건.
... A17: =_xlfn.TEXTJOIN("_",TRUE,C17,"dic",D17,E17) -> s1_dic_event_2_7 | B17: lbh9517_175126 | C17: s1 | D17: event_2 | E17: 7 | F17: 공명 결투 | G17: 차원핵 공명치에 따라 보상이 달라지는 결투 사건.

Sheet nexus_dic_relic
A1: lbh9517_175126 | B1: lbh9517_175126 | C1: lbh9517_175126 | D1: lbh9517_175126 | E1: lbh9517_175126 | F1: lbh9517_175126 | G1: lbh9517_175126 | H1: lbh9517_175126
A2: 고유값 | C2: 테마 id | D2: 새로운 타입 있을 경우 추가 | E2: 표시 순서 | F2: 아이콘 파일 이름 | G2: 이름 TID | H2: 설명 TID
A3: id | B3: export_id | C3: theme_id | D3: category | E3: index | F3: icon | G3: name | H3: desc
A4: s1_relic_001 | B4: lbh9517_175126 | C4: s1 | D4: relic | E4: 1 | G4: s1_relic_001_name | H4: s1_relic_001_desc
A5: s1_relic_002 | B5: lbh9517_175126 | C5: s1 | D5: relic | E5: 2 | G5: s1_relic_002_name | H5: s1_relic_002_desc
A6: s1_relic_003 | B6: lbh9517_175126 | C6: s1 | D6: relic | E6: 3 | G6: s1_relic_003_name | H6: s1_relic_003_desc
A7: s1_relic_004 | B7: lbh9517_175126 | C7: s1 | D7: relic | E7: 4 | G7: s1_relic_004_name | H7: s1_relic_004_desc
A8: s1_relic_005 | B8: lbh9517_175126 | C8: s1 | D8: relic | E8: 5 | G8: s1_relic_005_name | H8: s1_relic_005_desc
A9: s1_relic_006 | B9: lbh9517_175126 | C9: s1 | D9: relic | E9: 6 | G9: s1_relic_006_name | H9: s1_relic_006_desc
A10: s1_relic_007 | B10: lbh9517_175126 | C10: s1 | D10: relic | E10: 7 | G10: s1_relic_007_name | H10: s1_relic_007_desc
A11: s1_relic_008 | B11: lbh9517_175126 | C11: s1 | D11: relic | E11: 8 | G11: s1_relic_008_name | H11: s1_relic_008_desc
A12: s1_relic_009 | B12: lbh9517_175126 | C12: s1 | D12: relic | E12: 9 | G12: s1_relic_009_name | H12: s1_relic_009_desc
A13: s1_relic_010 | B13: lbh9517_175126 | C13: s1 | D13: relic | E13: 10 | G13: s1_relic_010_name | H13: s1_relic_010_desc
A14: s1_relic_011 | B14: lbh9517_175126 | C14: s1 | D14: relic | E14: 11 | G14: s1_relic_011_name | H14: s1_relic_011_desc
A15: s1_relic_012 | B15: lbh9517_175126 | C15: s1 | D15: relic | E15: 12 | G15: s1_relic_012_name | H15: s1_relic_012_desc
... A103: s1_relic_100 | B103: lbh9517_175126 | C103: s1 | D103: relic | E103: 100 | G103: s1_relic_100_name | H103: s1_relic_100_desc

Sheet nexus_dic_monster
A1: lbh9517_175126 | B1: lbh9517_175126 | C1: lbh9517_175126 | D1: lbh9517_175126 | E1: lbh9517_175126 | F1: lbh9517_175126 | G1: lbh9517_175126 | H1: lbh9517_175126
A2: 고유값 | C2: 테마 id | D2: 표시 순서 | E2: 테두리 파일명 | F2: 몬스터 id | G2: 몬스터 이름 | H2: 몬스터 설명
A3: id | B3: export_id | C3: theme_id | D3: index | E3: border_type | F3: monster_id | G3: name | H3: desc
A4: =_xlfn.TEXTJOIN("_",TRUE,C4,"dic_monster",D4) -> s1_dic_monster_1 | B4: lbh9517_175126 | C4: s1 | D4: 1 | E4: normal | F4: c2003_d_c_mpao005 | G4: 균열 보초병 | H4: 차원 균열 주변을 순찰하는 하급 개체.
A5: =_xlfn.TEXTJOIN("_",TRUE,C5,"dic_monster",D5) -> s1_dic_monster_2 | B5: lbh9517_175126 | C5: s1 | D5: 2 | E5: normal | F5: c2003_d_c_mpao006 | G5: 마력 오염체 | H5: 잔류 마력에 침식되어 공격성이 높아진 개체.
A6: =_xlfn.TEXTJOIN("_",TRUE,C6,"dic_monster",D6) -> s1_dic_monster_3 | B6: lbh9517_175126 | C6: s1 | D6: 3 | E6: normal | F6: c2003_d_c_mpao007 | G6: 버려진 정찰기 | H6: 낡은 정찰 장비가 폭주한 형태.
A7: =_xlfn.TEXTJOIN("_",TRUE,C7,"dic_monster",D7) -> s1_dic_monster_4 | B7: lbh9517_175126 | C7: s1 | D7: 4 | E7: normal | F7: c2003_d_c_mpao008 | G7: 공명 파편수 | H7: 차원핵 파편을 품은 소형 몬스터.
A8: =_xlfn.TEXTJOIN("_",TRUE,C8,"dic_monster",D8) -> s1_dic_monster_5 | B8: lbh9517_175126 | C8: s1 | D8: 5 | E8: elite | F8: c2003_d_c_mpao009 | G8: 균열 집행자 | H8: 침입자를 배제하도록 재구성된 정예 개체.
A9: =_xlfn.TEXTJOIN("_",TRUE,C9,"dic_monster",D9) -> s1_dic_monster_6 | B9: lbh9517_175126 | C9: s1 | D9: 6 | E9: elite | F9: c2003_d_c_mpao010 | G9: 차원 방랑자 | H9: 여러 차원을 떠돌며 전투 기록을 흡수한 존재.
A10: =_xlfn.TEXTJOIN("_",TRUE,C10,"dic_monster",D10) -> s1_dic_monster_7 | B10: lbh9517_175126 | C10: s1 | D10: 7 | E10: elite | F10: c2003_d_c_mpao011 | G10: 심연 감시자 | H10: 심층 구역의 진입자를 감시하는 강력한 개체.
A11: =_xlfn.TEXTJOIN("_",TRUE,C11,"dic_monster",D11) -> s1_dic_monster_8 | B11: lbh9517_175126 | C11: s1 | D11: 8 | E11: elite | F11: c2003_d_c_mpao012 | G11: 공명 수호자 | H11: 차원핵 공명에 반응해 강화되는 정예 수호자.
A12: =_xlfn.TEXTJOIN("_",TRUE,C12,"dic_monster",D12) -> s1_dic_monster_9 | B12: lbh9517_175126 | C12: s1 | D12: 9 | E12: boss | F12: c2003_d_c_mpao013 | G12: 허상의 군주 | H12: 나이트메어 테마의 최종 구역을 지키는 보스.

Sheet nexus_dic_reward
A1: lbh9517_175126 | B1: lbh9517_175126 | C1: lbh9517_175126 | D1: lbh9517_175126 | E1: lbh9517_175126 | F1: lbh9517_175126 | G1: lbh9517_175126 | H1: lbh9517_175126 | I1: lbh9517_175126 | J1: lbh9517_175126 | K1: lbh9517_175126 | L1: lbh9517_175126 | M1: lbh9517_175126 | N1: lbh9517_175126 | O1: lbh9517_175126 | P1: lbh9517_175126 | Q1: lbh9517_175126 | R1: lbh9517_175126
A2: 고유값 | C2: 테마 id | D2: 달성 퍼센트 | E2: 리워드 타입 | F2: 리워드 id | G2: 리워드 개수 | H2: 등급 설정 | I2: 세트 설정 | J2: 장비 옵션 설정 | K2: 장비 강화 LV 설정(현재 15만 사용 가능) | L2: 리워드 타입 | M2: 리워드 id | N2: 리워드 개수 | O2: 등급 설정 | P2: 세트 설정 | Q2: 장비 옵션 설정 | R2: 장비 강화 LV 설정(현재 15만 사용 가능)
A3: id | B3: export_id | C3: theme_id | D3: reward_rate | E3: reward_type_1 | F3: reward_id_1 | G3: reward_1_value | H3: *grade_rate_1 | I3: *set_drop_1 | J3: *equip_op_1 | K3: *equip_enchant_lv_1 | L3: reward_type_2 | M3: reward_id_2 | N3: reward_2_value | O3: *grade_rate_2 | P3: *set_drop_2 | Q3: *equip_op_2 | R3: *equip_enchant_lv_2
A4: =_xlfn.TEXTJOIN("_",TRUE,C4,"reward",D4*100) -> s1_reward_20 | B4: lbh9517_175126 | C4: s1 | D4: 0.2 | E4: item | F4: to_gold | G4: 100000
A5: =_xlfn.TEXTJOIN("_",TRUE,C5,"reward",D5*100) -> s1_reward_40 | B5: lbh9517_175126 | C5: s1 | D5: 0.4 | E5: item | F5: to_crystal | G5: 100
A6: =_xlfn.TEXTJOIN("_",TRUE,C6,"reward",D6*100) -> s1_reward_60 | B6: lbh9517_175126 | C6: s1 | D6: 0.6 | E6: item | F6: to_ticketrare | G6: 10 | L6: item | M6: to_stigma | N6: 500
A7: =_xlfn.TEXTJOIN("_",TRUE,C7,"reward",D7*100) -> s1_reward_80 | B7: lbh9517_175126 | C7: s1 | D7: 0.8 | E7: item | F7: to_powder | G7: 80 | L7: item | M7: to_mura | N7: 1
A8: =_xlfn.TEXTJOIN("_",TRUE,C8,"reward",D8*100) -> s1_reward_100 | B8: lbh9517_175126 | C8: s1 | D8: 1 | E8: item | F8: ma_border175 | G8: 1 | L8: item | M8: to_ticketmoon | N8: 5

Sheet nexus_normal_mission
A1: lbh9517_175126 | B1: lbh9517_175126 | C1: lbh9517_175126 | E1: lbh9517_175126 | F1: lbh9517_175126 | G1: lbh9517_175126 | H1: lbh9517_175126 | I1: lbh9517_175126 | J1: lbh9517_175126 | K1: lbh9517_175126 | L1: lbh9517_175126 | M1: lbh9517_175126 | N1: lbh9517_175126 | O1: lbh9517_175126 | P1: lbh9517_175126 | Q1: lbh9517_175126 | R1: lbh9517_175126 | S1: lbh9517_175126 | T1: lbh9517_175126 | U1: lbh9517_175126 | V1: lbh9517_175126
A2: 고유값 | C2: 테마 id | D2: id 생성용 | E2: 미션 타이틀 | F2: 조건 타입 | G2: 값 | H2: 미션 텍스트 | I2: 아이템 타입 | J2: 완료 보상 | K2: 보상 값 | L2: 등급 설정 | M2: 세트 설정 | N2: 장비 옵션 설정 | O2: 장비 강화 LV 설정(현재 15만 사용 가능) | P2: 아이템 타입 | Q2: 완료 보상 | R2: 보상 값 | S2: 등급 설정 | T2: 세트 설정 | U2: 장비 옵션 설정 | V2: 장비 강화 LV 설정(현재 15만 사용 가능)
A3: id | B3: export_id | C3: theme_id | E3: mission_title | F3: condition | G3: value | H3: mission_text | I3: item_type_1 | J3: reward_id_1 | K3: reward_value_1 | L3: *grade_rate_1 | M3: *set_drop_1 | N3: *equip_op_1 | O3: *equip_enchant_lv_1 | P3: item_type_2 | Q3: reward_id_2 | R3: reward_value_2 | S3: *grade_rate_2 | T3: *set_drop_2 | U3: *equip_op_2 | V3: *equip_enchant_lv_2
A4: =_xlfn.TEXTJOIN("_",TRUE,C4,"mission_normal",D4) -> s1_mission_normal_1 | B4: lbh9517_175126 | C4: s1 | D4: 1 | E4: normal_mission_title | F4: clear_battle_level | G4: 1 | H4: =VLOOKUP(F4,레퍼런스!$E$143:$I$148,4,FALSE) -> clear_battle_level_text | I4: item | J4: to_gold | K4: 100000 | P4: item | Q4: to_stigma | R4: 300
A5: =_xlfn.TEXTJOIN("_",TRUE,C5,"mission_normal",D5) -> s1_mission_normal_2 | B5: lbh9517_175126 | C5: s1 | D5: 2 | E5: normal_mission_title | F5: clear_with_hero | G5: c5001 | H5: =VLOOKUP(F5,레퍼런스!$E$143:$I$148,4,FALSE) -> clear_with_hero_text | I5: item | J5: to_gold | K5: 200000 | P5: item | Q5: to_stigma | R5: 300
A6: =_xlfn.TEXTJOIN("_",TRUE,C6,"mission_normal",D6) -> s1_mission_normal_3 | B6: lbh9517_175126 | C6: s1 | D6: 3 | E6: normal_mission_title | F6: clear_event | G6: s1_evt_001 | H6: =VLOOKUP(F6,레퍼런스!$E$143:$I$148,4,FALSE) -> clear_event_text | I6: item | J6: to_gold | K6: 300000 | P6: item | Q6: to_stigma | R6: 300
A7: =_xlfn.TEXTJOIN("_",TRUE,C7,"mission_normal",D7) -> s1_mission_normal_4 | B7: lbh9517_175126 | C7: s1 | D7: 4 | E7: normal_mission_title | F7: recruit_hero | G7: c5001 | H7: =VLOOKUP(F7,레퍼런스!$E$143:$I$148,4,FALSE) -> recruit_hero_text | I7: item | J7: to_gold | K7: 400000 | P7: item | Q7: to_stigma | R7: 300
A8: =_xlfn.TEXTJOIN("_",TRUE,C8,"mission_normal",D8) -> s1_mission_normal_5 | B8: lbh9517_175126 | C8: s1 | D8: 5 | E8: normal_mission_title | F8: collect_relic | G8: s1_relic_095 | H8: =VLOOKUP(F8,레퍼런스!$E$143:$I$148,4,FALSE) -> collect_relic_text | I8: item | J8: to_gold | K8: 500000 | P8: item | Q8: to_stigma | R8: 300

Sheet nexus_special_mission
A1: lbh9517_175126 | B1: lbh9517_175126 | C1: lbh9517_175126 | E1: lbh9517_175126 | F1: lbh9517_175126 | G1: lbh9517_175126 | H1: lbh9517_175126 | I1: lbh9517_175126 | J1: lbh9517_175126 | K1: lbh9517_175126 | L1: lbh9517_175126 | M1: lbh9517_175126 | N1: lbh9517_175126 | O1: lbh9517_175126 | P1: lbh9517_175126 | Q1: lbh9517_175126 | R1: lbh9517_175126 | S1: lbh9517_175126 | T1: lbh9517_175126 | U1: lbh9517_175126 | V1: lbh9517_175126 | W1: lbh9517_175126 | X1: lbh9517_175126 | Y1: lbh9517_175126 | Z1: lbh9517_175126
A2: 고유값 | C2: 테마 id | D2: id 생성용 | E2: 미션 타이틀 | F2: 해당 미션 시작 | G2: 해당 미션 종료 기간 | H2: 해당 미션 시작 | I2: 해당 미션 종료 기간 | J2: 조건 타입 | K2: 값 | L2: 미션 텍스트 | M2: 아이템 타입 | N2: 완료 보상 | O2: 보상 값 | P2: 등급 설정 | Q2: 세트 설정 | R2: 장비 옵션 설정 | S2: 장비 강화 LV 설정(현재 15만 사용 가능) | T2: 아이템 타입 | U2: 완료 보상 | V2: 보상 값 | W2: 등급 설정 | X2: 세트 설정 | Y2: 장비 옵션 설정 | Z2: 장비 강화 LV 설정(현재 15만 사용 가능)
A3: id | B3: export_id | C3: theme_id | E3: mission_title | F3: start | G3: end | H3: start_zl | I3: end_zl | J3: condition | K3: value | L3: mission_text | M3: item_type_1 | N3: reward_id_1 | O3: reward_value_1 | P3: *grade_rate_1 | Q3: *set_drop_1 | R3: *equip_op_1 | S3: *equip_enchant_lv_1 | T3: item_type_2 | U3: reward_id_2 | V3: reward_value_2 | W3: *grade_rate_2 | X3: *set_drop_2 | Y3: *equip_op_2 | Z3: *equip_enchant_lv_2
A4: =_xlfn.TEXTJOIN("_",TRUE,C4,"mission_season",D4) -> s1_mission_season_1 | B4: lbh9517_175126 | C4: s1 | D4: 1 | E4: special_mission_title | F4: 46282 | G4: =F4+7 -> 46289 | H4: =F4+21 -> 46303 | I4: =H4+7 -> 46310 | J4: clear_battle_level | K4: 2 | L4: =VLOOKUP(J4,레퍼런스!$E$143:$I$148,4,FALSE) -> clear_battle_level_text | M4: item | N4: to_ticketrare_wish | O4: 5 | T4: item | U4: to_crystal | V4: 300
A5: =_xlfn.TEXTJOIN("_",TRUE,C5,"mission_season",D5) -> s1_mission_season_2 | B5: lbh9517_175126 | C5: s1 | D5: 2 | E5: special_mission_title | F5: =G4 -> 46289 | G5: =F5+7 -> 46296 | H5: =I4 -> 46310 | I5: =H5+7 -> 46317 | J5: clear_with_hero | K5: c2184 | L5: =VLOOKUP(J5,레퍼런스!$E$143:$I$148,4,FALSE) -> clear_with_hero_text | M5: item | N5: to_ticketrare_wish | O5: 5 | T5: item | U5: to_crystal | V5: 300
A6: =_xlfn.TEXTJOIN("_",TRUE,C6,"mission_season",D6) -> s1_mission_season_3 | B6: lbh9517_175126 | C6: s1 | D6: 3 | E6: special_mission_title | F6: =G5 -> 46296 | G6: =F6+7 -> 46303 | H6: =I5 -> 46317 | I6: =H6+7 -> 46324 | J6: clear_event | K6: s1_evt_002 | L6: =VLOOKUP(J6,레퍼런스!$E$143:$I$148,4,FALSE) -> clear_event_text | M6: item | N6: to_ticketrare_wish | O6: 5 | T6: item | U6: to_crystal | V6: 300
A7: =_xlfn.TEXTJOIN("_",TRUE,C7,"mission_season",D7) -> s1_mission_season_4 | B7: lbh9517_175126 | C7: s1 | D7: 4 | E7: special_mission_title | F7: =G6 -> 46303 | G7: =F7+7 -> 46310 | H7: =I6 -> 46324 | I7: =H7+7 -> 46331 | J7: recruit_hero | K7: c2184 | L7: =VLOOKUP(J7,레퍼런스!$E$143:$I$148,4,FALSE) -> recruit_hero_text | M7: item | N7: to_ticketrare_wish | O7: 5 | T7: item | U7: to_crystal | V7: 300
A8: =_xlfn.TEXTJOIN("_",TRUE,C8,"mission_season",D8) -> s1_mission_season_5 | B8: lbh9517_175126 | C8: s1 | D8: 5 | E8: special_mission_title | F8: =G7 -> 46310 | G8: =F8+7 -> 46317 | H8: =I7 -> 46331 | I8: =H8+7 -> 46338 | J8: collect_relic | K8: s1_relic_100 | L8: =VLOOKUP(J8,레퍼런스!$E$143:$I$148,4,FALSE) -> collect_relic_text | M8: item | N8: to_ticketrare_wish | O8: 5 | T8: item | U8: to_crystal | V8: 300
A9: =_xlfn.TEXTJOIN("_",TRUE,C9,"mission_season",D9) -> s1_mission_season_6 | B9: lbh9517_175126 | C9: s1 | D9: 6 | E9: special_mission_title | F9: =G8 -> 46317 | G9: =F9+7 -> 46324 | H9: =I8 -> 46338 | I9: =H9+7 -> 46345 | J9: clear_battle_level | K9: 3 | L9: =VLOOKUP(J9,레퍼런스!$E$143:$I$148,4,FALSE) -> clear_battle_level_text | M9: item | N9: to_ticketrare_wish | O9: 5 | T9: item | U9: to_crystal | V9: 300

Sheet nexus_investment
A1: lbh9517_175126 | B1: lbh9517_175126 | C1: lbh9517_175126 | D1: lbh9517_175126 | E1: lbh9517_175126 | F1: lbh9517_175126 | G1: lbh9517_175126
A2: 고유값 | B2: 테마 id | C2: id 생성용 | E2: 투자량 | F2: 투자 효과 텍스트 | G2: 활성화 효과
A3: id | B3: theme_id | D3: export_id | E3: invest_cnt | F3: invest_text | G3: nexus_effect_id
A4: =B4&"_investment_"&C4 -> s1_investment_1 | B4: s1 | C4: 1 | D4: lbh9517_175126 | E4: 25 | F4: =A4&"_desc" -> s1_investment_1_desc | G4: s1_investment_1
A5: =B5&"_investment_"&C5 -> s1_investment_2 | B5: s1 | C5: 2 | D5: lbh9517_175126 | E5: 100 | F5: =A5&"_desc" -> s1_investment_2_desc | G5: s1_investment_2
A6: =B6&"_investment_"&C6 -> s1_investment_3 | B6: s1 | C6: 3 | D6: lbh9517_175126 | E6: 200 | F6: =A6&"_desc" -> s1_investment_3_desc | G6: s1_investment_3
A7: =B7&"_investment_"&C7 -> s1_investment_4 | B7: s1 | C7: 4 | D7: lbh9517_175126 | E7: 325 | F7: =A7&"_desc" -> s1_investment_4_desc | G7: s1_investment_4
A8: =B8&"_investment_"&C8 -> s1_investment_5 | B8: s1 | C8: 5 | D8: lbh9517_175126 | E8: 500 | F8: =A8&"_desc" -> s1_investment_5_desc | G8: s1_investment_5

Sheet 레퍼런스
A1: nexus_out_system — 시트 레퍼런스
A3: ▸ nexus_theme_level
A4: 테마 패스 레벨별 필요 EXP 및 보상. dic_collect_story로 도감 스토리 해금.
A5: 필드명 | B5: 설명
A6: id | B6: 패스 레벨 고유 ID (예: s1_pass_1)
A7: export_id | B7: -
A8: theme_id | B8: → nexus_main.theme_id (FK)
A9: level | B9: 패스 레벨 (1~99)
A10: need_exp_value | B10: 해당 레벨 도달에 필요한 EXP 수치
A11: reward_id_1 | B11: 보상 아이템 ID (예: to_gold)
A12: reward_value_1 | B12: 보상 수량
A13: dic_collect_story | B13: 해금될 도감 스토리 ID
A14: main_reward | B14: y 입력 시 메인 리워드로 표시
A15: *grade_rate_1 | B15: 장비 보상 등급 설정
A16: *set_drop_1 | B16: 장비 세트 설정
... A18: *equip_enchant_lv_1 | B18: 장비 강화 LV (현재 15만 사용 가능)
A20: ▸ nexus_hall_level
A21: 홀(함교) 레벨별 필요 재화 및 보상 정의. 최대 10레벨. reward_type: node/item/story 지원.
A22: 필드명 | B22: 설명 | D22: reward_1_type_1 | E22: reward_1_type_2 | F22: reward_1_cnt
A23: id | B23: 레벨 고유 ID (예: s1_level_1) | D23: node | E23: permission | F23: N
A24: export_id | B24: - | D24: item | E24: item_id | F24: cnt
A25: theme_id | B25: → nexus_main.theme_id (FK) | D25: story | E25: story_id
A26: level | B26: 홀 레벨 (1~10)
A27: level_bg | B27: 레벨 별 메인 배경
A28: level_image | B28: 해당 레벨의 홀 이미지 파일명
A29: level_require_item_id | B29: 레벨 업 필요 아이템 ID (예: to_gold)
A30: level_require_item_value | B30: 레벨 업 필요 아이템 수량
A31: reward_type_1 | B31: 보상 타입 1 (node / item / story)
A32: reward_id_1 | B32: 보상 ID 1 (예: permission, to_gold, story_id)
A33: reward_1_value | B33: 보상 수량 1
A34: *grade_rate_1 | B34: 장비 보상 등급 설정
A35: *set_drop_1 | B35: 장비 세트 설정
A36: *equip_op_1 | B36: 장비 옵션 설정
A37: *equip_enchant_lv_1 | B37: 장비 강화 LV
... A44: *equip_enchant_lv_2 | B44: 장비 강화 LV
A46: ▸ nexus_node
A47: 연구 노드 트리 구조. column/row 좌표계로 위치 정의. active_item으로 활성화 비용 지정. condition_node로 선행 노드 최대 5개 지정. category는 nexus_node_category.category(FK).
A48: 필드명 | B48: 설명
A49: id | B49: 노드 고유 ID (예: s1_node_normal_1_3 = theme_카테고리_컬럼_행)
A50: export_id | B50: -
...
